model
name = main
size = 20 20 17
scale = 0.05
resize = model
rotation = 90 0 0
origin = +z
flatten = -z
shell = Outline 0.25
material lighting = smooth, roughness = 0.75, fade = true, deform = 4 1, ao = #01F 3 -6
  colors = A:#A30 F:#FDD S:#040
material lighting = smooth, roughness = 0.75, fade = true, deform = 1 0.75, ao = #01F 3 -6
  colors = B:#A30
material lighting = smooth, roughness = 0.75, fade = true, emissive = #F50 2, deform = 1 0.75
  colors = C:#F50
material type = basic, lighting = smooth, roughness = 0, refractionRatio = 1, side = back
  colors = Outline:#000
voxels
-------------------- -------------------- -------------------- -------------------- -------------------- -------------------- -------------------- -------------------- -------------------- -------SSS---------- -------SSS---------- -------------------- -------------------- -------------------- -------------------- -------------------- -------------------- -------------------- -------------------- -------------------- 
-------------------- -------------------- -------------------- -------------------- -------------------- -------------------- -------------------- -------------------- -------------------- --------SSS--------- --------SSS--------- -------------------- -------------------- -------------------- -------------------- -------------------- -------------------- -------------------- -------------------- -------------------- 
-------------------- -------------------- -------------------- -------------------- -------------------- -------------------- -------------------- -------------------- ---------SS--------- --------SSSS-------- --------SSSS-------- ---------SS--------- -------------------- -------------------- -------------------- -------------------- -------------------- -------------------- -------------------- -------------------- 
-------------------- -------------------- -------------------- -------------------- -------------------- -------AAAAAA------- ------AAAAAAAA------ -----AAA----AAA----- -----AA--SS--AA----- -----AA-SSSS-AA----- -----AA-SSSS-AA----- -----AA--SS--AA----- ------AA----AA------ ------AAAAAAAA------ -------AAAAAA------- -------------------- -------------------- -------------------- -------------------- -------------------- 
-------------------- -------------------- -------------------- ------AAAAAAAA------ -----AAAAAAAAAA----- ----AAAAAAAAAAAA---- ---AAAAAAAAAAAAAA--- ---AAAAAAAAAAAAAA--- ---AAAAAAAAAAAAAA--- ----AAAAAAAAAAAA---- ----AAAAAAAAAAAA---- ---AAAAAAAAAAAAAA--- ----AAAAAAAAAAAA---- ---AAAACCCCCCAAAA--- ----AAAACCCCAAAA---- -----AAAAAAAAAA----- ------AAA--AAA------ -------------------- -------------------- -------------------- 
-------------------- -------------------- -------------------- ----AAAAAAAAAAAA---- ---AAAAAAAAAAAAAA--- --AAAACCCCCCCCAAAA-- --AAAAACCCCCCAAAAA-- --AAACCCCCCCCCCAAA-- --AAACCCCCCCCCCAAA-- ---AAACCCCCCCCAAA--- ---AAACCCCCCCCAAA--- --AAACCCCCCCCCCAAA-- ---AAAAC----CAAAA--- --AAACC------CCAAA-- --AAAACC----CCAAAA-- ---AAAAAAAAAAAAAA--- ----AAAAAAAAAAAA---- ------AAAAAAAA------ -------------------- -------------------- 
-------------------- -------------------- ------AAA--AAA------ ---AAAAAAAAAAAAAA--- --AAAACCCCCCCCAAAA-- --AACCCC----CCCCAA-- -AAACCCCC--CCCCCAAA- -AAAC----------CAAA- -AAAC----------CAAA- ---AAAC------CAAA--- ---AAC--------CAA--- -AAAC----------CAAA- --AAACC------CCAAA-- -AAACC--------CCAAA- --AAAC--------CAAA-- --AAA--AAAAAA--AAA-- ---AA--AAAAAA--AA--- ----A--AAAAAA--A---- -------------------- -------------------- 
-------------------- -------------------- ----AAAAA--AAAAA---- ---AAAAAAAAAAAAAA--- --AAACCCCCCCCCCAAA-- -AAACC--------CCAAA- -AACC----------CCAA- -AAC------------CAA- -AAC------------CAA- --AAAC---C----CAAA-- --AAAC---C----CAAA-- -AAAC----------CAAA- -AAAC----------CAAA- -AACC----------CCAA- -AAAC----------CAAA- --AAA---AAAA---AAA-- ---AAA--AAAA--AAA--- ----AA--AAAA--AA---- -----A--------A----- -------------------- 
-------------------- -------------------- ----AAAAA--AAAAA---- ---AAAAAAAAAAAAAA--- --AACCCCCCCCCCCCAA-- -AACC----------CCAA- -AAC------------CAA- -AAC------------CAA- -AAC------------CAA- --AAC----CC----CAA-- --AAC----CC----CAA-- -AAC------------CAA- -AAC------------CAA- -AAC------------CAA- -AAC------------CAA- --AAAA---AA---AAAA-- ---AAA---AA---AAA--- ----AAA--AA--AAA---- -----AA------AA----- -------------------- 
-------------------- -------------------- ---AAAAAA--AAAAAA--- --AAAAAAAAAAAAAAAA-- --AACCCCCCCCCCCCAA-- -AACC----------CCAA- -AAC------------CAA- -AAC------------CAA- -AAC------------CAA- --AAC----CC----CAA-- --AAC----CC----CAA-- -AAC------------CAA- -AAC------------CAA- -AAC------------CAA- -AAC------------CAA- --AAAAAAAAAAAAAAAA-- --AAAAAAAAAAAAAAAA-- ---AAAAAAAAAAAAAA--- -----AAAA--AAAA----- -------------------- 
-------------------- -------------------- ---AAAAAA--AAAAAA--- --AAAAAAAAAAAAAAAA-- --AACCCCCCCCCCCCAA-- -AACC----------CCAA- -AAC------------CAA- -AAC------------CAA- -AAC------------CAA- --AAC----AA----CAA-- --AAC----------CAA-- -AAC------------CAA- -AAC------------CAA- -AAC------------CAA- -AAC------------CAA- --AA--AA-AA-AA--AA-- --AAA-AA-AA-AA-AAA-- ---AA-AA-AA-AA-AA--- -------------------- -------------------- 
-------------------- -------------------- ----AAAAA--AAAAA---- ---AAAAAAAAAAAAAA--- --AACCCCCCCCCCCCAA-- -AACC----------CCAA- -AAC------------CAA- -AAC------------CAA- -AAC-----FF-----CAA- --AAC---FFFF---CAA-- --AAC---FFFF---CAA-- -AAC-----FF-----CAA- -AAC------------CAA- -AAC------------CAA- -AAC------------CAA- --AA--BB-BB-BB--AA-- ---AA-BB-BB-BB-AA--- ----A-BB-BB-BB-A---- -------------------- -------------------- 
-------------------- -------------------- ----AAAAA--AAAAA---- ---AAAAAAAAAAAAAA--- --AAACCCCCCCCCCAAA-- -AAACC--------CCAAA- -AACC----------CCAA- -AAC------------CAA- -AAC-----FF-----CAA- --AAAC--FFFF--CAAA-- --AAAC--FFFF--CAAA-- -AAAC----FF----CAAA- -AAC------------CAA- -AAC------------CAA- -AAAC----------CAAA- --AA------------AA-- ---A------------A--- ----A----------A---- -------------------- -------------------- 
-------------------- -------------------- ------AAA--AAA------ ---AAAAAAAAAAAAAA--- --AAAACCCCCCCCAAAA-- --AACCC------CCCAA-- -AAACCCC----CCCCAAA- -AAAC----------CAAA- -AAAC----FF----CAAA- ---AAC--FFFF--CAA--- ---AAC--FFFF--CAA--- -AAAC----FF----CAAA- -AAA------------AAA- -AAA------------AAA- --AAAC--------CAAA-- --AAAA-BB--BB-AAAA-- ---AA--BB--BB--AA--- -------BB--BB------- -------------------- -------------------- 
-------------------- -------------------- -------------------- ----AAAAAAAAAAAA---- ---AAAAAAAAAAAAAA--- --AAAACCCCCCCCAAAA-- --AAAAACCCCCCAAAAA-- --AAACC------CCAAA-- --AAAC---FF---CAAA-- ---AAC--FFFF--CAA--- ---AAC--FFFF--CAA--- --AAAC---FF---CAAA-- --AAAA--------AAAA-- --AAAAA------AAAAA-- --AAAAAA----AAAAAA-- ---AAAAAAAAAAAAAA--- ----AAAAAAAAAAAA---- -----AAAAAAAAAA----- -------------------- -------------------- 
-------------------- -------------------- -------------------- ------AAAAAAAA------ -----AAAAAAAAAA----- ----AAAAAAAAAAAA---- ---AAAAAAAAAAAAAA--- ---AAAACCCCCCAAAA--- ---AAACCCCCCCCAAA--- ----AAAAAAAAAAAA---- ----AAAAAAAAAAAA---- ---AAACCAAAACCAAA--- ---AAAAAAAAAAAAAA--- ---AAAAAAAAAAAAAA--- ----AAAAAAAAAAAA---- -----AAAAAAAAAA----- ------AAA--AAA------ -------------------- -------------------- -------------------- 
-------------------- -------------------- -------------------- -------------------- -------------------- -------AAAAAA------- ------AAAAAAAA------ -----AAAAAAAAAA----- -----AAAAAAAAAA----- -----AAAAAAAAAA----- -----AAAAAAAAAA----- -----AAAAAAAAAA----- -----AAAAAAAAAA----- ------AAAAAAAA------ -------AAAAAA------- -------------------- -------------------- -------------------- -------------------- -------------------- 
