model
name = main
size = 9 20 7
scale = 0.05
origin = -y
clamp = -y
shell = Outline 0.25
material lighting = smooth, fade = true, deform = 1 1
  colors = Y:#FA0 R:#200
material lighting = smooth, roughness = 0.5, fade = true, deform = 5 0.5, warp = 0.5 0.25
  colors = G:#0C0 S:#050
material type = basic, lighting = smooth, roughness = 0, refractionRatio = 1, side = back
  colors = Outline:#000
voxels
--------- --------- --------- --------- --------- --------- --------- --------- G-------G G-------G G-------G G-------G GG-----GG --------- --------- --------- --------- --------- --------- --------- 
--------- --------- --------- --------- --------- --------- --------- G-------G G-------G G-------G G-------G GG-----GG GG-----GG --------- --------- --------- --------- --------- --------- --------- 
----S---- ----S---- ----S---- ----S---- ----S---- ----S---- G---S---G G---S---G S---S---S S---S---S S---S---S SSSSSSSSS ----S---- ----S---- ----S---- ----S---- ----S---- --------- --------- --------- 
--------- --------- --------- --------- --------- --------- --------- G-------G G-------G G-------G G-------G GG-----GG GG-----GG --------- --------- --------- ----S---- --------- --------- --------- 
--------- --------- --------- --------- --------- --------- --------- --------- G-------G G-------G G-------G G-------G GG-----GG --------- --------- ---SSS--- ---SSS--- ---SSS--- --------- --------- 
--------- --------- --------- --------- --------- --------- --------- --------- --------- --------- --------- --------- --------- --------- --YYYYY-- --YRRRY-- --YRRRY-- --YRRRY-- --YYYYY-- --------- 
--------- --------- --------- --------- --------- --------- --------- --------- --------- --------- --------- --------- --------- --YYYYY-- -YYYYYYY- -YY---YY- -YY---YY- -YY---YY- -YYYYYYY- --YYYYY-- 
