model
name = path
revision = 8514
size = 98 40 127
origin = -y
shell = Outline 0.25
material type = toon, lighting = smooth, deform = 1 1
  colors = B:#F0B429 E:#DE911D
material type = basic, lighting = smooth, roughness = 0, refractionRatio = 1, side = back
  colors = Outline:#000
voxels
1951-2(5B3915-)7B95-3E3814-9B94-3E3811-12B94-3E3809-10B3-2B3904-11B3-2B82-3E3819-2(4B3-)2B82-3E3818-5B3-8B83-3E3818-5B3-8B3904-17B95-3E3806-16B95-3E3806-8B3-5B95-3E3807-6B5-3B3908-4B5-2B3910-3B5-B3910-5B3-3B2(3909-11B)3908-11B3909-11B91-3E3814-2(11B91-5E3813-)11B91-5E3814-11B91-3E3815-12B3909-11B3908-5B3-5B2(3907-4B5-4B)3906-5B5-3B3906-7B3-4B3906-14B2(3905-15B)3905-14B3907-12B3908-12B3909-11B3911-8B3913-7B3912-2(9B3911-)9B2(3912-7B)3910-11B83-3B3820-14B84-3B3812-3B2-16B85-3B96-B-B3709-23B86-B3808-15B-9B3889-3B2-15B3-9B65-3E16-B3801-23B-10B64-5E14-2B3799-36B64-5E3815-29B3-4B64-5E3805-2B7-19B3-7B5-4B64-3E3804-4B7-18B5-6B5-4B3870-6B5-18B7-5B5-5B3864-B3-8B3-19B7-6B3-6B3864-34B7-15B3864-35B5-15B3865-36B3-16B3865-14B3-37B3866-2(13B5-29B3-3B3867-)13B5-5B3-21B3-3B3867-14B3-6B3-28B3868-21B3-29B3867-16B2-23B5-7B3867-14B4-23B5-7B3867-2B-10B6-3B2-16B6-7B93-3E3776-8B11-5BE3B-5B6-9B72-3E17-3E76-E3700-3B-2B13-3B3EB3-3B7-9B72-3E17-3E75-3E3720-2BE15-9B72-3E96-E3738-9B3910-9B3911-9B3910-10B3909-5B3-4B3908-5B3-4B3907-6B3-4B2(3907-13B)3908-11B3909-11B90-3E3817-9B91-3E3818-7B92-3E3820-3B154849-
